INFO:runner:Using loss: gaussian.
INFO:runner:Using temporary directory /var/folders/9b/_dhnw9_17kgb24l4cq75nq9h0000gn/T/tmp1wv6ic2t.
gefundener dataset Path: /Users/wiebkezink/Documents/Uni Münster/MA/dataset
INFO:runner:Loading /dataset dataset from /Users/wiebkezink/Documents/Uni Münster/MA/dataset.
Computed weighting 10.0-quantile-lower bound: nan.
Removed temporary directory /var/folders/9b/_dhnw9_17kgb24l4cq75nq9h0000gn/T/tmp1wv6ic2t.
Traceback (most recent call last):
  File "/Users/wiebkezink/Documents/Uni Münster/MA/Canopy-Height-Prediction/venv/lib/python3.9/site-packages/pandas/core/indexes/base.py", line 3805, in get_loc
    return self._engine.get_loc(casted_key)
  File "index.pyx", line 167, in pandas._libs.index.IndexEngine.get_loc
  File "index.pyx", line 196, in pandas._libs.index.IndexEngine.get_loc
  File "pandas/_libs/hashtable_class_helper.pxi", line 7081, in pandas._libs.hashtable.PyObjectHashTable.get_item
  File "pandas/_libs/hashtable_class_helper.pxi", line 7089, in pandas._libs.hashtable.PyObjectHashTable.get_item
KeyError: 'path'

The above exception was the direct cause of the following exception:

Traceback (most recent call last):
  File "/Users/wiebkezink/Documents/Uni Münster/MA/Canopy-Height-Prediction/training/main.py", line 122, in <module>
    runner.run()
  File "/Users/wiebkezink/Documents/Uni Münster/MA/Canopy-Height-Prediction/training/runner.py", line 981, in run
    loaders = self.get_dataloaders()
  File "/Users/wiebkezink/Documents/Uni Münster/MA/Canopy-Height-Prediction/training/runner.py", line 265, in get_dataloaders
    fixvalData = FixValDataset(data_path=data_path, dataframe=fix_val_dataframe,
  File "/Users/wiebkezink/Documents/Uni Münster/MA/Canopy-Height-Prediction/training/config.py", line 65, in __init__
    self.files = list(self.df["path"].apply(lambda x: os.path.join(data_path, x)))
  File "/Users/wiebkezink/Documents/Uni Münster/MA/Canopy-Height-Prediction/venv/lib/python3.9/site-packages/pandas/core/frame.py", line 4102, in __getitem__
    indexer = self.columns.get_loc(key)
  File "/Users/wiebkezink/Documents/Uni Münster/MA/Canopy-Height-Prediction/venv/lib/python3.9/site-packages/pandas/core/indexes/base.py", line 3812, in get_loc
    raise KeyError(key) from err
KeyError: 'path'
