INFO:runner:Using loss: gaussian.
INFO:runner:Using temporary directory /var/folders/9b/_dhnw9_17kgb24l4cq75nq9h0000gn/T/tmpn0lj45ze.
gefundener dataset Path: /Users/wiebkezink/Documents/Uni Münster/MA/dataset
INFO:runner:Loading /dataset dataset from /Users/wiebkezink/Documents/Uni Münster/MA/dataset.
Removed temporary directory /var/folders/9b/_dhnw9_17kgb24l4cq75nq9h0000gn/T/tmpn0lj45ze.
Traceback (most recent call last):
  File "/Users/wiebkezink/Documents/Uni Münster/MA/Canopy-Height-Prediction/venv/lib/python3.9/site-packages/pandas/core/indexes/base.py", line 3805, in get_loc
    return self._engine.get_loc(casted_key)
  File "index.pyx", line 167, in pandas._libs.index.IndexEngine.get_loc
  File "index.pyx", line 196, in pandas._libs.index.IndexEngine.get_loc
  File "pandas/_libs/hashtable_class_helper.pxi", line 7081, in pandas._libs.hashtable.PyObjectHashTable.get_item
  File "pandas/_libs/hashtable_class_helper.pxi", line 7089, in pandas._libs.hashtable.PyObjectHashTable.get_item
KeyError: 'has_corrupt_s2_channel_flag'

The above exception was the direct cause of the following exception:

Traceback (most recent call last):
  File "/Users/wiebkezink/Documents/Uni Münster/MA/Canopy-Height-Prediction/training/main.py", line 122, in <module>
    runner.run()
  File "/Users/wiebkezink/Documents/Uni Münster/MA/Canopy-Height-Prediction/training/runner.py", line 981, in run
    loaders = self.get_dataloaders()
  File "/Users/wiebkezink/Documents/Uni Münster/MA/Canopy-Height-Prediction/training/runner.py", line 261, in get_dataloaders
    trainData = PreprocessedSatelliteDataset(data_path=data_path, dataframe=train_dataframe, image_transforms=transformDict['train'], label_transforms=label_transforms, joint_transforms=joint_transforms,
  File "/Users/wiebkezink/Documents/Uni Münster/MA/Canopy-Height-Prediction/training/config.py", line 100, in __init__
    df = df[df["has_corrupt_s2_channel_flag"] == False]
  File "/Users/wiebkezink/Documents/Uni Münster/MA/Canopy-Height-Prediction/venv/lib/python3.9/site-packages/pandas/core/frame.py", line 4102, in __getitem__
    indexer = self.columns.get_loc(key)
  File "/Users/wiebkezink/Documents/Uni Münster/MA/Canopy-Height-Prediction/venv/lib/python3.9/site-packages/pandas/core/indexes/base.py", line 3812, in get_loc
    raise KeyError(key) from err
KeyError: 'has_corrupt_s2_channel_flag'
